Workbook

Sheet TOC
E2: 🏠 TABLA DE CONTENIDOS
E3: Hoja 1 · Datos Personales del Hogar
E4: Hoja 2 · Ingresos
E5: Hoja 3 · Gastos
E6: Hoja 4 · Ahorro
E7: Hoja 5 · Ahorro Especifico
E8: Hoja 6 · Estrategias por Edad
E10: By: Alberto Elizalde

Sheet 1. Datos Personales
E2: 🏠 ASESOR FINANCIERO DEL HOGAR
E3: Hoja 1 · Datos Personales del Hogar
E4: Complete los datos de cada integrante del hogar (máximo 8 personas). Las celdas en blanco son editables.
E6: Número de personas en el hogar: | H6: ↑ Ingrese entre 1 y 8
E8: Nombre Completo | F8: Parentesco / Rol | G8: Fecha de Nacimiento | H8: Edad | I8: Ocupación / Actividad
F9: Titular / Jefe de hogar
F10: Pareja / Conyuge
F11: Hijo/a 1
F12: Hijo/a 2
F13: Hijo/a 3
F14: Otro familiar 1
F15: Otro familiar 2
F16: Otro familiar 3
E19: Información General del Hogar
E20: País / Ciudad de residencia:
E21: Tipo de vivienda:
E22: Estrato socioeconómico:
E23: Correo electrónico de contacto:
E24: Teléfono de contacto:
E25: Fecha de elaboración del plan:
E28: NOTA: Este asesor financiero es una herramienta de planificación personal. Los datos ingresados son confidenciales y de uso exclusivo del hogar.
E31: By: Alberto Elizalde

Sheet 2. Ingresos
E2: 💰 REGISTRO DE INGRESOS DEL HOGAR
E3: Registre todos los ingresos mensuales de cada integrante del hogar
E6: Fuente de Ingreso / Integrante | F6: Tipo de Ingreso | G6: Frecuencia | H6: Monto Mensual | I6: Monto Anual | J6: % del Total | K6: Horas de Trabajo | L6: Salario por Hora | M6: Observaciones
E7: Titular – Salario / Sueldo fijo | F7: Laboral dependiente | G7: Mensual | H7: 0 | I7: =H7*12 -> 0 | J7: =IF(H$21=0,0,H7/H$21) -> 0 | L7: =IFERROR(H7/(K7*24),"")
E8: Titular – Ingresos independientes | F8: Laboral independiente | G8: Variable | H8: 0 | I8: =H8*12 -> 0 | J8: =IF(H$21=0,0,H8/H$21) -> 0 | L8: =IFERROR(H8/(K8*24),"")
E9: Titular – Horas extra / Bonos | F9: Laboral dependiente | G9: Ocasional | H9: 0 | I9: =H9*12 -> 0 | J9: =IF(H$21=0,0,H9/H$21) -> 0 | L9: =IFERROR(H9/(K9*24),"")
E10: Cónyuge / Pareja – Salario fijo | F10: Laboral dependiente | G10: Mensual | H10: 0 | I10: =H10*12 -> 0 | J10: =IF(H$21=0,0,H10/H$21) -> 0 | L10: =IFERROR(H10/(K10*24),"")
E11: Cónyuge / Pareja – Ingresos independientes | F11: Laboral independiente | G11: Variable | H11: 0 | I11: =H11*12 -> 0 | J11: =IF(H$21=0,0,H11/H$21) -> 0 | L11: =IFERROR(H11/(K11*24),"")
E12: Hijo/a 1 – Ingresos | F12: Laboral dependiente | G12: Mensual | H12: 0 | I12: =H12*12 -> 0 | J12: =IF(H$21=0,0,H12/H$21) -> 0 | L12: =IFERROR(H12/(K12*24),"")
E13: Hijo/a 2 – Ingresos | F13: Laboral dependiente | G13: Mensual | H13: 0 | I13: =H13*12 -> 0 | J13: =IF(H$21=0,0,H13/H$21) -> 0 | L13: =IFERROR(H13/(K13*24),"")
E14: Otro familiar – Ingresos | F14: Laboral dependiente | G14: Mensual | H14: 0 | I14: =H14*12 -> 0 | J14: =IF(H$21=0,0,H14/H$21) -> 0 | L14: =IFERROR(H14/(K14*24),"")
E15: Arriendos / Alquileres | F15: Pasivo | G15: Mensual | H15: 0 | I15: =H15*12 -> 0 | J15: =IF(H$21=0,0,H15/H$21) -> 0 | L15: =IFERROR(H15/(K15*24),"")
E16: Dividendos / Inversiones | F16: Pasivo | G16: Variable | H16: 0 | I16: =H16*12 -> 0 | J16: =IF(H$21=0,0,H16/H$21) -> 0 | L16: =IFERROR(H16/(K16*24),"")
E17: Pensión / Jubilación | F17: Otro | G17: Mensual | H17: 0 | I17: =H17*12 -> 0 | J17: =IF(H$21=0,0,H17/H$21) -> 0 | L17: =IFERROR(H17/(K17*24),"")
E18: Transferencias / Subsidios | F18: Otro | G18: Variable | H18: 0 | I18: =H18*12 -> 0 | J18: =IF(H$21=0,0,H18/H$21) -> 0 | L18: =IFERROR(H18/(K18*24),"")
... E20: Otros ingresos 2 | F20: Otro | G20: Variable | H20: 0 | I20: =H20*12 -> 0 | J20: =IF(H$21=0,0,H20/H$21) -> 0 | L20: =IFERROR(H20/(K20*24),"")
E21: TOTAL INGRESOS DEL HOGAR | H21: =SUM(H7:H20) -> 0 | I21: =SUM(I7:I20) -> 0 | J21: 1
E24: Resumen de Ingresos
E25: Categoría | F25: Monto Mensual | G25: % Participación | H25: Observación
E26: Ingresos Laborales Dependientes | F26: =SUMIF(F7:F20,"Laboral dependiente",H7:H20) -> 0 | G26: =IF(H21=0,0,F26/H21) -> 0 | H26: Salarios fijos
E27: Ingresos Independientes | F27: =SUMIF(F7:F20,"laboral independiente",H7:H20) -> 0 | G27: =IF(H21=0,0,F27/H21) -> 0 | H27: Freelance, negocios
E28: Ingresos Pasivos | F28: =SUMIF(F7:F20,"Pasivo",H7:H20) -> 0 | G28: =IF(H21=0,0,F28/H21) -> 0 | H28: Arriendos, dividendos
E29: Otros | F29: =SUMIF(F7:F20,"Otro",H7:H20) -> 0 | G29: =IF(H21=0,0,F29/H21) -> 0 | H29: Subsidios, otros
E32: By: Alberto Elizalde

Sheet 3. Gastos
A1: 1
E2: 📊 REGISTRO DE GASTOS DEL HOGAR
E3: Registre todos los gastos mensuales del hogar por categoría
E6: Categoría de Gasto | F6: Subcategoría / Detalle | G6: Monto Mensual | H6: Monto Anual | I6: % del Total | J6: Tipo
E7: VIVIENDA | F7: Arriendo / Cuota hipoteca | G7: 0 | H7: =G7*12 -> 0 | I7: =IF(G$62=0,0,G7/G$62) -> 0 | J7: Fijo
E8: VIVIENDA | F8: Agua | G8: 0 | H8: =G8*12 -> 0 | I8: =IF(G$62=0,0,G8/G$62) -> 0 | J8: Fijo
E9: VIVIENDA | F9: Luz | G9: 0 | H9: =G9*12 -> 0 | I9: =IF(G$62=0,0,G9/G$62) -> 0 | J9: Fijo
E10: VIVIENDA | F10: Gas | G10: 0 | H10: =G10*12 -> 0 | I10: =IF(G$62=0,0,G10/G$62) -> 0 | J10: Fijo
E11: VIVIENDA | F11: Internet / Telefonia | G11: 0 | H11: =G11*12 -> 0 | I11: =IF(G$62=0,0,G11/G$62) -> 0 | J11: Fijo
E12: VIVIENDA | F12: Cable | G12: 0 | H12: =G12*12 -> 0 | I12: =IF(G$62=0,0,G12/G$62) -> 0 | J12: Fijo
E13: VIVIENDA | F13: Telefonia | G13: 0 | H13: =G13*12 -> 0 | I13: =IF(G$62=0,0,G13/G$62) -> 0 | J13: Fijo
E14: VIVIENDA | F14: Administración / Cuotas HOA | G14: 0 | H14: =G14*12 -> 0 | I14: =IF(G$62=0,0,G14/G$62) -> 0 | J14: Fijo
E15: VIVIENDA | F15: Mantenimiento | G15: 0 | H15: =G15*12 -> 0 | I15: =IF(G$62=0,0,G15/G$62) -> 0 | J15: Variable
E16: VIVIENDA | F16: Reparaciones | G16: 0 | H16: =G16*12 -> 0 | I16: =IF(G$62=0,0,G16/G$62) -> 0 | J16: Variable
E17: ALIMENTACIÓN | F17: Mercado / Supermercado | G17: 0 | H17: =G17*12 -> 0 | I17: =IF(G$62=0,0,G17/G$62) -> 0 | J17: Fijo
E18: ALIMENTACIÓN | F18: Restaurantes / Comidas fuera | G18: 0 | H18: =G18*12 -> 0 | I18: =IF(G$62=0,0,G18/G$62) -> 0 | J18: Variable
... E59: GASTOS VARIOS | F59: Otros gastos | G59: 0 | H59: =G59*12 -> 0 | I59: =IF(G$62=0,0,G59/G$62) -> 0 | J59: Variable
E60: GASTOS VARIOS | F60: Otros gastos | H60: =G60*12 -> 0 | I60: =IF(G$62=0,0,G60/G$62) -> 0 | J60: Variable
E61: GASTOS VARIOS | F61: Otros gastos | H61: =G61*12 -> 0 | I61: =IF(G$62=0,0,G61/G$62) -> 0 | J61: Variable
E62: TOTAL GASTOS DEL HOGAR | G62: =SUM(G7:G61) -> 0 | H62: =SUM(H7:H61) -> 0 | I62: =SUM(I7:I61) -> 0
E66: Resumen por Categoría Principal
E67: Categoría | F67: Total Mensual | G67: Total Anual | H67: % del Total | I67: Semáforo | J67: Recomendación %
E68: VIVIENDA | F68: =SUMIF(tbl_gastos[Categoría de Gasto],E68,tbl_gastos[Monto Mensual]) -> 0 | G68: =F68*12 -> 0 | H68: =IF(G62=0,0,F68/G62) -> 0 | I68: =IF(H68>J68,"⚠️ Revisar","✅ OK") -> ✅ OK | J68: 0.25
E69: ALIMENTACIÓN | F69: =SUMIF(tbl_gastos[Categoría de Gasto],E69,tbl_gastos[Monto Mensual]) -> 0 | G69: =F69*12 -> 0 | H69: =IF(G62=0,0,F69/G62) -> 0 | I69: =IF(H69>J69,"⚠️ Revisar","✅ OK") -> ✅ OK | J69: 0.15
E70: TRANSPORTE | F70: =SUMIF(tbl_gastos[Categoría de Gasto],E70,tbl_gastos[Monto Mensual]) -> 0 | G70: =F70*12 -> 0 | H70: =IF(G62=0,0,F70/G62) -> 0 | I70: =IF(H70>J70,"⚠️ Revisar","✅ OK") -> ✅ OK | J70: 0.1
E71: SALUD | F71: =SUMIF(tbl_gastos[Categoría de Gasto],E71,tbl_gastos[Monto Mensual]) -> 0 | G71: =F71*12 -> 0 | H71: =IF(G62=0,0,F71/G62) -> 0 | I71: =IF(H71>J71,"⚠️ Revisar","✅ OK") -> ✅ OK | J71: 0.05
E72: EDUCACIÓN | F72: =SUMIF(tbl_gastos[Categoría de Gasto],E72,tbl_gastos[Monto Mensual]) -> 0 | G72: =F72*12 -> 0 | H72: =IF(G62=0,0,F72/G62) -> 0 | I72: =IF(H72>J72,"⚠️ Revisar","✅ OK") -> ✅ OK | J72: 0.1
E73: ROPA Y CALZADO | F73: =SUMIF(tbl_gastos[Categoría de Gasto],E73,tbl_gastos[Monto Mensual]) -> 0 | G73: =F73*12 -> 0 | H73: =IF(G62=0,0,F73/G62) -> 0 | I73: =IF(H73>J73,"⚠️ Revisar","✅ OK") -> ✅ OK | J73: 0.05
E74: ENTRETENIMIENTO | F74: =SUMIF(tbl_gastos[Categoría de Gasto],E74,tbl_gastos[Monto Mensual]) -> 0 | G74: =F74*12 -> 0 | H74: =IF(G62=0,0,F74/G62) -> 0 | I74: =IF(H74>J74,"⚠️ Revisar","✅ OK") -> ✅ OK | J74: 0.05
E75: DEUDAS / CRÉDITOS | F75: =SUMIF(tbl_gastos[Categoría de Gasto],E75,tbl_gastos[Monto Mensual]) -> 0 | G75: =F75*12 -> 0 | H75: =IF(G62=0,0,F75/G62) -> 0 | I75: =IF(H75>J75,"⚠️ Revisar","✅ OK") -> ✅ OK | J75: 0.15
E76: SEGUROS | F76: =SUMIF(tbl_gastos[Categoría de Gasto],E76,tbl_gastos[Monto Mensual]) -> 0 | G76: =F76*12 -> 0 | H76: =IF(G62=0,0,F76/G62) -> 0 | I76: =IF(H76>J76,"⚠️ Revisar","✅ OK") -> ✅ OK | J76: 0.03
E77: CUIDADO PERSONAL | F77: =SUMIF(tbl_gastos[Categoría de Gasto],E77,tbl_gastos[Monto Mensual]) -> 0 | G77: =F77*12 -> 0 | H77: =IF(G62=0,0,F77/G62) -> 0 | I77: =IF(H77>J77,"⚠️ Revisar","✅ OK") -> ✅ OK | J77: 0.03
E78: MASCOTAS | F78: =SUMIF(tbl_gastos[Categoría de Gasto],E78,tbl_gastos[Monto Mensual]) -> 0 | G78: =F78*12 -> 0 | H78: =IF(G62=0,0,F78/G62) -> 0 | I78: =IF(H78>J78,"⚠️ Revisar","✅ OK") -> ✅ OK | J78: 0.02
E79: GASTOS VARIOS | F79: =SUMIF(tbl_gastos[Categoría de Gasto],E79,tbl_gastos[Monto Mensual]) -> 0 | G79: =F79*12 -> 0 | H79: =IF(G62=0,0,F79/G62) -> 0 | I79: =IF(H79>J79,"⚠️ Revisar","✅ OK") -> ✅ OK | J79: 0.02
E80: TOTAL GASTOS DEL HOGAR | G80: =SUM(G68:G79) -> 0 | H80: =SUM(H68:H79) -> 0 | J80: =SUM(J68:J79) -> 1
E84: Necesidades VS Deseos
E85: Categorias | F85: Total | G85: Propuesto
E86: Necesidades | F86: =SUM(F68:F73) -> 0 | G86: ='4. Ahorro'!G19 -> 0
E87: Deseos | F87: =SUM(F74:F79) -> 0 | G87: ='4. Ahorro'!G20 -> 0
E90: By: Alberto Elizalde

Sheet 4. Ahorro
E2: 🏦 PLAN DE AHORRO DEL HOGAR
E3: Monitoree su capacidad de ahorro y establezca metas mensuales
E6: Resumen Financiero Mensual
E7: Total Ingresos Mensuales | H7: ='2. Ingresos'!H21 -> 0
E8: Total Gastos Mensuales | H8: ='3. Gastos'!G62 -> 0 | I8: =IF(H8>H7," GASTOS EXCEDIDOS","")
E9: Capacidad de Ahorro Bruta | H9: =H7-H8 -> 0 | I9: =IF(H9<0,"NO CAPACIDAD DE AHORRO","")
E11: Ahorro Mensual
E12: Meta de Ahorro Mensual (ingrese %) | H12: 0.2
E13: Meta de Ahorro en $ (calculado) | H13: =H7*H12 -> 0
E14: Diferencia (Ahorro real vs Meta) | H14: =H9-H13 -> 0
E17: Regla de: 50 / 30 / 20
E18: Categoría | F18: % Recomendado | G18: $ Recomendado | H18: $ Real | I18: Diferencia | J18: Estado
E19: Necesidades (vivienda, comida, servicios, etc…) | F19: 0.5 | G19: =H7*0.5 -> 0 | H19: ='3. Gastos'!F86 -> 0 | I19: =H19-G19 -> 0 | J19: =IF(H19<G19,"✅ OK","⚠️ Revisar") -> ⚠️ Revisar
E20: Deseos (entretenimiento, ropa, extras) | F20: 0.3 | G20: =H7*0.3 -> 0 | H20: ='3. Gastos'!F87 -> 0 | I20: =H20-G20 -> 0 | J20: =IF(H20<G20,"✅ OK","⚠️ Revisar") -> ⚠️ Revisar
E21: Ahorro e inversión | F21: 0.2 | G21: =H7*0.2 -> 0 | H21: =H9 -> 0 | I21: =H21-G21 -> 0 | J21: =IF(H21<G21,"✅ OK","⚠️ Revisar") -> ⚠️ Revisar
E24: Registro Mensual de Ahorro – Año en Curso
E25: Mes | F25: Ingresos | G25: Gastos | H25: Ahorro Real | I25: % Ahorro | J25: Acumulado
E26: Enero | F26: =$H$7 -> 0 | G26: =$H$8 -> 0 | H26: =F26-G26 -> 0 | I26: =IF(F26=0,0,H26/F26) -> 0 | J26: =H26 -> 0
E27: Febrero | F27: =$H$7 -> 0 | G27: =$H$8 -> 0 | H27: =F27-G27 -> 0 | I27: =IF(F27=0,0,H27/F27) -> 0 | J27: =J26+H27 -> 0
E28: Marzo | F28: =$H$7 -> 0 | G28: =$H$8 -> 0 | H28: =F28-G28 -> 0 | I28: =IF(F28=0,0,H28/F28) -> 0 | J28: =J27+H28 -> 0
E29: Abril | F29: =$H$7 -> 0 | G29: =$H$8 -> 0 | H29: =F29-G29 -> 0 | I29: =IF(F29=0,0,H29/F29) -> 0 | J29: =J28+H29 -> 0
E30: Mayo | F30: =$H$7 -> 0 | G30: =$H$8 -> 0 | H30: =F30-G30 -> 0 | I30: =IF(F30=0,0,H30/F30) -> 0 | J30: =J29+H30 -> 0
E31: Junio | F31: =$H$7 -> 0 | G31: =$H$8 -> 0 | H31: =F31-G31 -> 0 | I31: =IF(F31=0,0,H31/F31) -> 0 | J31: =J30+H31 -> 0
E32: Julio | F32: =$H$7 -> 0 | G32: =$H$8 -> 0 | H32: =F32-G32 -> 0 | I32: =IF(F32=0,0,H32/F32) -> 0 | J32: =J31+H32 -> 0
E33: Agosto | F33: =$H$7 -> 0 | G33: =$H$8 -> 0 | H33: =F33-G33 -> 0 | I33: =IF(F33=0,0,H33/F33) -> 0 | J33: =J32+H33 -> 0
E34: Septiembre | F34: =$H$7 -> 0 | G34: =$H$8 -> 0 | H34: =F34-G34 -> 0 | I34: =IF(F34=0,0,H34/F34) -> 0 | J34: =J33+H34 -> 0
E35: Octubre | F35: =$H$7 -> 0 | G35: =$H$8 -> 0 | H35: =F35-G35 -> 0 | I35: =IF(F35=0,0,H35/F35) -> 0 | J35: =J34+H35 -> 0
E36: Noviembre | F36: =$H$7 -> 0 | G36: =$H$8 -> 0 | H36: =F36-G36 -> 0 | I36: =IF(F36=0,0,H36/F36) -> 0 | J36: =J35+H36 -> 0
E37: Diciembre | F37: =$H$7 -> 0 | G37: =$H$8 -> 0 | H37: =F37-G37 -> 0 | I37: =IF(F37=0,0,H37/F37) -> 0 | J37: =J36+H37 -> 0
E38: TOTAL ANUAL | F38: =SUM(F26:F37) -> 0 | G38: =SUM(G26:G37) -> 0 | H38: =SUM(H26:H37) -> 0 | I38: =IF(F38=0,0,H38/F38) -> 0 | J38: =J37 -> 0
E43: By: Alberto Elizalde

Sheet 5. Ahorro Específico
E2: 🎯 AHORRO PARA METAS ESPECÍFICAS
E3: Defina hasta 8 metas de ahorro específicas con seguimiento mensual
I4: Hoy (dd/mm/yyyy) | J4: =J5 -> 46122
J5: =TODAY() -> 46122
E8: META 1: Fondo de Emergencia (3-6 meses de gastos)
E9: Nombre / Descripción de la meta: | G9: Fondo de Emergencia (3-6 meses de gastos)
E10: Monto total requerido ($): | G10: 120000
E11: Fecha límite para alcanzar la meta: | G11: 46753
E12: Meses restantes para la meta: | G12: =DATEDIF($J$4,G11,"m") -> 20
E13: Ahorro mensual necesario ($): | G13: =IF(G12=0,0,G10/G12) -> 6000
E14: Ahorro ya acumulado ($): | G14: 60000
E15: Porcentaje alcanzado (%): | G15: =IF(G10=0,0,G14/G10) -> 0.5 | I15: =IF(G15>=1,"🎉 META ALCANZADA!",IF(G15>=0.75,"🟢 75%+ logrado",IF(G15>=0.5,"🟡 50%+ logrado",IF(G15>=0.25,"🟠 25%+ logrado","🔴 Iniciando")))) -> 🟡 50%+ logrado
E16: Ahorro mensual que destina ($): | G16: 6000
E20: META 2: Vacaciones / Viaje familiar
E21: Nombre / Descripción de la meta: | G21: Vacaciones / Viaje familiar
E22: Monto total requerido ($): | G22: 60000
E23: Fecha límite para alcanzar la meta: | G23: 46372 | I23: DD/MM/YYYY
E24: Meses restantes para la meta: | G24: =DATEDIF($J$4,G23,"m") -> 8
E25: Ahorro mensual necesario ($): | G25: =IF(G24=0,0,G22/G24) -> 7500
E26: Ahorro ya acumulado ($): | G26: 18000
E27: Porcentaje alcanzado (%): | G27: =IF(G22=0,0,G26/G22) -> 0.3 | I27: =IF(G27>=1,"🎉 META ALCANZADA!",IF(G27>=0.75,"🟢 75%+ logrado",IF(G27>=0.5,"🟡 50%+ logrado",IF(G27>=0.25,"🟠 25%+ logrado","🔴 Iniciando")))) -> 🟠 25%+ logrado
E28: Ahorro mensual que destina ($):
E32: META 3: Compra de vehículo
E33: Nombre / Descripción de la meta: | G33: Compra de vehículo
E34: Monto total requerido ($): | G34: 480000
E35: Fecha límite para alcanzar la meta: | G35: 47484 | I35: DD/MM/YYYY
E36: Meses restantes para la meta: | G36: =DATEDIF($J$4,G35,"m") -> 44
E37: Ahorro mensual necesario ($): | G37: =IF(G36=0,0,G34/G36) -> 10909.091
E38: Ahorro ya acumulado ($): | G38: 0
E39: Porcentaje alcanzado (%): | G39: =IF(G34=0,0,G38/G34) -> 0 | I39: =IF(G39>=1,"🎉 META ALCANZADA!",IF(G39>=0.75,"🟢 75%+ logrado",IF(G39>=0.5,"🟡 50%+ logrado",IF(G39>=0.25,"🟠 25%+ logrado","🔴 Iniciando")))) -> 🔴 Iniciando
E40: Ahorro mensual que destina ($): | G40: 0
E44: META 4: Cuota inicial vivienda
E45: Nombre / Descripción de la meta: | G45: Cuota inicial vivienda
E46: Monto total requerido ($): | G46: 0
E47: Fecha límite para alcanzar la meta: | G47: DD/MM/YYYY | I47: DD/MM/YYYY
E48: Meses restantes para la meta: | G48: =DATEDIF($J$4,G47,"m") -> #VALUE!
E49: Ahorro mensual necesario ($): | G49: =IF(G48=0,0,G46/G48) -> #VALUE!
E50: Ahorro ya acumulado ($): | G50: 0
E51: Porcentaje alcanzado (%): | G51: =IF(G46=0,0,G50/G46) -> 0 | I51: =IF(G51>=1,"🎉 META ALCANZADA!",IF(G51>=0.75,"🟢 75%+ logrado",IF(G51>=0.5,"🟡 50%+ logrado",IF(G51>=0.25,"🟠 25%+ logrado","🔴 Iniciando")))) -> 🔴 Iniciando
E52: Ahorro mensual que destina ($): | G52: 0
...

Sheet 6. Estrategias por Edad
E2: 📈 ESTRATEGIAS FINANCIERAS POR ETAPA DE VIDA
E3: Guía de estrategias financieras personalizadas según la edad de cada integrante del hogar
E6: 🎓 15 – 25 AÑOS · Etapa de Formación y Primeros Pasos Financieros
E7: En esta etapa la persona se encuentra en proceso de formación académica o inicio de vida laboral. Los ingresos suelen ser bajos o inexistentes, pero es el momento ideal para construir hábitos financieros sólidos que determinarán el bienestar económico futuro. El tiempo es el mayor activo disponible.
E8: 🎯 Objetivos Principales | G8: ⚡ Estrategias Clave
E9: • Abrir la primera cuenta de ahorros y mantenerla activa | G9: ▶ Regla del 10%: Ahorrar mínimo el 10% de cualquier ingreso recibido, sin excepción.
E10: • Evitar deudas de consumo (tarjetas de crédito sin respaldo) | G10: ▶ Fondo de emergencia inicial: Acumular entre 1 y 3 meses de gastos básicos como colchón de seguridad.
E11: • Iniciar con pequeñas inversiones en fondos de bajo riesgo | G11: ▶ Educación financiera: Leer al menos 2 libros de finanzas personales por año (ej: Padre Rico Padre Pobre, El Hombre Más Rico de Babilonia).
E12: • Construir un historial crediticio responsable | G12: ▶ Evitar deuda mala: No adquirir créditos de consumo para bienes que se deprecian (ropa, electrónicos, etc.).
E13: • Establecer el hábito del ahorro desde el primer ingreso | G13: ▶ Primer portafolio: Explorar fondos de inversión indexados (ETFs) con montos pequeños desde $10-$50/mes.
E14: • Invertir en educación y desarrollo de habilidades | G14: ▶ Presupuesto básico: Aplicar la regla 50/30/20: 50% necesidades, 30% deseos, 20% ahorro.
E15: 📊 Indicadores Clave de Salud Financiera
E16: Indicador | F16: Meta Recomendada | G16: Indicador | H16: Meta Recomendada
E17: Tasa de ahorro mínima | F17: 10% de ingresos | G17: Fondo de emergencia | H17: 1-3 meses de gastos
E18: Deuda total | F18: < 10% de ingresos | G18: Inversión mensual | H18: Desde $10 USD/mes
E19: ⚠️ Errores Comunes a Evitar
E20: ✗ Gastar todo el primer sueldo en bienes de consumo
E21: ✗ No tener cuenta de ahorros propia
E22: ✗ Pedir préstamos a familiares sin plan de pago
E23: ✗ Ignorar la importancia del historial crediticio
E26: 💼 25 – 35 AÑOS · Etapa de Consolidación y Construcción de Patrimonio
E27: Esta es la década más importante para la construcción de riqueza. Los ingresos comienzan a estabilizarse, se forman hogares, se adquieren primeras propiedades y se inician familias. Las decisiones financieras tomadas en esta etapa tienen un impacto exponencial gracias al interés compuesto. Es el momento de maximizar el ahorro e inversión.
E28: 🎯 Objetivos Principales | G28: ⚡ Estrategias Clave
E29: • Consolidar el fondo de emergencia (3-6 meses de gastos) | G29: ▶ Regla del 20-30%: Ahorrar e invertir entre el 20% y 30% de los ingresos totales.
E30: • Iniciar o fortalecer el plan de pensión/jubilación | G30: ▶ Pensión voluntaria: Maximizar aportes a fondos de pensión voluntaria o cuentas de ahorro para el retiro.
E31: • Considerar la compra de vivienda propia | G31: ▶ Diversificación: Invertir en acciones, bonos, bienes raíces y fondos indexados para reducir el riesgo.
E32: • Diversificar las fuentes de ingreso | G32: ▶ Seguro de vida: Adquirir seguro de vida y de invalidez para proteger a la familia.
E33: • Proteger el patrimonio con seguros adecuados | G33: ▶ Deuda estratégica: Usar deuda únicamente para activos que se valoricen (vivienda, educación, negocio).
E34: • Planificar financieramente la llegada de hijos | G34: ▶ Ingreso pasivo: Comenzar a construir fuentes de ingreso pasivo: arriendos, dividendos, regalías.
E35: 📊 Indicadores Clave de Salud Financiera
E36: Indicador | F36: Meta Recomendada | G36: Indicador | H36: Meta Recomendada
E37: Tasa de ahorro mínima | F37: 20-30% de ingresos | G37: Fondo de emergencia | H37: 3-6 meses de gastos
E38: Deuda total | F38: < 30% de ingresos | G38: Patrimonio neto | H38: 1-2x ingreso anual
E39: ⚠️ Errores Comunes a Evitar
E40: ✗ Posponer el inicio del plan de pensión
E41: ✗ Adquirir vivienda sin análisis financiero previo
E42: ✗ No tener seguro de vida con dependientes a cargo
E43: ✗ Mantener deudas de consumo de alto interés
E46: 🚀 35 – 45 AÑOS · Etapa de Aceleración y Maximización del Patrimonio
E47: En esta etapa los ingresos suelen estar en su punto más alto de la carrera profesional. Las responsabilidades familiares son mayores (hijos en edad escolar/universitaria, padres mayores), pero también la capacidad de ahorro e inversión. Es el momento de acelerar la acumulación de patrimonio y preparar el terreno para una jubilación cómoda.
...
